I'm sorry, but an uncaught exception occurred.

While running game code:
  File "game/script.rpy", line 14347, in script
    narrator_nvl "虽然说要「相信自己」，但实际上真正能做到的人，往往都不需要被别人这么说。"
Exception: Sayer 'narrator_nvl' is not defined.

-- Full Traceback ------------------------------------------------------------

Full traceback:
  File "game/script.rpy", line 14347, in script
    narrator_nvl "虽然说要「相信自己」，但实际上真正能做到的人，往往都不需要被别人这么说。"
  File "K:\Ren'py环境\renpy-7.3.5-sdk\renpy\ast.py", line 678, in execute
    who = eval_who(self.who, self.who_fast)
  File "K:\Ren'py环境\renpy-7.3.5-sdk\renpy\ast.py", line 576, in eval_who
    raise Exception("Sayer '%s' is not defined." % who.encode("utf-8"))
Exception: Sayer 'narrator_nvl' is not defined.

Windows-8-6.2.9200
Ren'Py 7.3.5.606
候鸟 加长试玩内测版 Demo0.2
Thu Jun 30 19:14:53 2022
